Workbook
Name IQ_CH: 110000
Name IQ_CQ: 5000
Name IQ_CY: 10000
Name IQ_DAILY: 500000
Name IQ_FH: 100000
Name IQ_FQ: 500
Name IQ_FY: 1000
Name IQ_LTM: 2000
Name IQ_MONTH: 15000
Name IQ_NTM: 6000
Name IQ_WEEK: 50000
Name IQ_YTD: 3000

Sheet Table of Contents
A1: Table of Contents
A2: Directions to Use This Model/File
A3: Note that the best way to use this file is to turn off automatic calculations in excel (Formulas tab-->Calculation Options-->Manual). When adjusting the Monte Carlo Inputs, use the "Calculate Now" button to run all 5,000 simulations. Note, this may take a moment. For best results, let your fingers rest while the model is calculating.
A5: Tab | B5: Description | C5: Uses
A6: Tesla Valuation Inputs | B6: This tab has all of our input variables for our Monte Carlo analysis, including a range for each variable. These inputs feed directly into our Monte Carlo Single Simulation tab, and to the price and adoption tables from the Valuation ASP Tables tab, which then feed into the Monte Carlo Single Simulation tab. Here, we also calculate the bull, bear, and expected value from the Monte Carlo Simulation Output tab. | C6: Can change the range of inputs for a monte carlo valuation of Tesla and view how it changes the Bull, Bear, and Expected values.
A7: Valuation ASP Tables | B7: This tab has our tables for Tesla's average vehicle selling price, price per mile for ride-hail service, and ride-hail adoption curve. These tables feed into the Monte Carlo Single Simulation tab. | C7: Can change the average selling price assumptions for the Tesla Valuation.
A8: Monte Carlo Single Simulation | B8: This tab takes the variables from our Tesla Valuation Inputs tab and calculates single simulation runs using values within the ranges we laid out for each variable. | C8: View a single simulation of the monte carlo valuation.
A9: Monte Carlo Simulation Output | B9: This tab is an output of 5,000 simulation runs of our Monte Carlo. We have highlighted some key outputs from the model in each column. | C9: View simulation outputs after you change Monte Carlo Inputs.

Sheet ARK Disclosure
A2: This work is licensed under a Creative Commons Attribution-Non-Commercial 4.0 International License.
A3: You may not use the material for commercial purposes without first obtaining written permission.
A5: 2025, ARK Investment Management LLC. All content is original and has been researched and produced by ARK Investment Management LLC (“ARK”) unless otherwise stated herein.
A7: In this tool, you can investigate the assumptions, criteria and methodology used in this Monte Carlo simulation to determine the value of a single security in future years. A Monte Carlo simulation is intended to assist in understanding the impact of risk and uncertainty in forecasting or predicting a future event. The simulation works by assigning multiple values to a set of variables to achieve multiple results, and then averaging those results to obtain an estimate; here, this simulation is being used to predict the price of a single security in future years. The tool is inherently limited by its nature, including the assumption of perfectly efficient markets. ARK has used its research to determine what it believes are reasonable ranges for variables modelled as well as which business lines will have the biggest determination on the security’s future value. The tool is designed to forecast the price of a single security over time. Please refer to the blog for additional information on the assumptions, criteria and methodology used, and the limitations of this tool. The results may vary with each use and over time. This tool relies on historical information of the modelled security, including publicly available financial data sources, and analysis of that data by ARK and by third-parties, combined with ARK’s research to forecast over a future time horizon. Please note that key inputs are included in the Tesla Valuation Inputs tab of this GitHub document. The reader is urged to use extreme caution when considering the forecasted performance, as it is inherently subjective and reflects ARK’s long term positive view of the company. There is no guarantee that any results will align with the forecasted performance, and they might not be predictive. This tool is intended to analyze a single security, and we note that other companies were not considered that may have characteristics similar or superior to those being analyzed. This tool generates outcomes that are hypothetical in nature.
A9: The forecasts and price estimates herein are subject to revision by ARK Invest (“ARK”) and provided solely as a guide to current expectations. Forecasts regarding broad markets and individual issuers are not, and are not intended to be, representative of any ARK-managed investment product or the characteristics of any ARK portfolio.
A11: FORECASTS ARE HYPOTHETICAL AND HIGHLY SPECULATIVE, AND PRESENT MANY RISKS AND LIMITATIONS. While ARK believes that there is a sound basis for the forecasts presented, they are provided for illustrative purposes only and no representations are made as to their accuracy.
A13: This material is intended only to provide observations and views of the author(s) at the time of writing, both of which are subject to change at any time without prior notice. Certain of the statements contained herein are statements of future expectations and other forward-looking statements that are based on ARK's current views and assumptions and involve known and unknown risks and uncertainties that could cause actual results, performance or events to differ materially from those expressed or implied in such statements. Past performance is no guarantee of future results. Equities may decline in value due to both real and perceived general market, economic, and industry conditions.
A15: ARK does not have investment banking, consulting, or any type of fee-paying relationship with the subject company.

Sheet Tesla Valuation Inputs
A1: Tesla Valuation Inputs
A2: Blue text indicates assumptions that can be altered; altering one input may require altering another input in order to get reasonable results. | B2: Current Price | C2: 2031 Expected Value | D2: Bear | E2: Bull | F2: CAGR | G2: Notes:
A3: Black text indicates cells with formulas or cells with static values that are not meant to be altered. | B3: 354.72 | C3: =AVERAGE('Monte Carlo Simulation Output'!Q6:Q5005) -> 4341.5216 | D3: =QUARTILE('Monte Carlo Simulation Output'!Q6:Q5005,1) -> 3308.9775 | E3: =QUARTILE('Monte Carlo Simulation Output'!Q6:Q5005,3) -> 5052.5564 | F3: =(C3/B3)^(1/F4)-1 -> 0.61712644 | G3: Note that occasionally simulation will produce an error when certain variables grow extremely large in very rare scenarios. Re-run simulation in this case and error will likely disappear.
A4: Note: To utilize the Monte Carlo, you need to use the "Calculate Now" button in excel, not "Calculate Sheet". | B4: Dates | C4: 46311 | D4: 48213 | F4: =(D4-C4)/365 -> 5.2109589 | G4: Please also note that each simulation run contains variance that may cause the bull, bear and expected values to differ in between runs.
A5: Values are in millions unless otherwise specified except for per share amounts, multiples, and ratios.
A9: Key Drivers | B9: Minimum | C9: Downside | D9: Upside | E9: Maximum | G9: MC Input | H9: Random Number Generator | I9: Median
A10: Max annual vehicle production increase (given management bandwidth constraints) | B10: 0.2 | C10: 0.35 | D10: 0.45 | E10: 0.6 | G10: =IF(I10=D10,I10,IF(_xlfn.NORM.INV(H10,I10,(D10-I10))<B10,B10,IF(_xlfn.NORM.INV(H10,I10,(D10-I10))>E10,E10,_xlfn.NORM.INV(H10,I10,(D10-I10))))) -> 0.40507328 | H10: =RAND() -> 0.54040953 | I10: =('Tesla Valuation Inputs'!D10-'Tesla Valuation Inputs'!C10)/2+'Tesla Valuation Inputs'!C10 -> 0.4
A11: Miles traveled per robotaxi (not in millions) | B11: 30000 | C11: 55000 | D11: 75000 | E11: 100000 | G11: =IF(I11=D11,I11,IF(_xlfn.NORM.INV(H11,I11,(D11-I11))<B11,B11,IF(_xlfn.NORM.INV(H11,I11,(D11-I11))>E11,E11,_xlfn.NORM.INV(H11,I11,(D11-I11))))) -> 74200.303 | H11: =RAND() -> 0.82122155 | I11: =('Tesla Valuation Inputs'!D11-'Tesla Valuation Inputs'!C11)/2+'Tesla Valuation Inputs'!C11 -> 65000
A12: Takeover time for autonomous adoption (years between 10% and 90% market saturation) | B12: 2 | C12: 3 | D12: 9 | E12: 15 | G12: =IF(I12=D12,I12,IF(_xlfn.NORM.INV(H12,I12,(D12-I12))<B12,B12,IF(_xlfn.NORM.INV(H12,I12,(D12-I12))>E12,E12,_xlfn.NORM.INV(H12,I12,(D12-I12))))) -> 5.2343191 | H12: =RAND() -> 0.3992739 | I12: =('Tesla Valuation Inputs'!D12-'Tesla Valuation Inputs'!C12)/2+'Tesla Valuation Inputs'!C12 -> 6
A13: Max annual Optimi production increase (given management bandwidth constraints) | B13: 1.5 | C13: 2.5 | D13: 3 | E13: 5 | G13: =IF(I13=D13,I13,IF(_xlfn.NORM.INV(H13,I13,(D13-I13))<B13,B13,IF(_xlfn.NORM.INV(H13,I13,(D13-I13))>E13,E13,_xlfn.NORM.INV(H13,I13,(D13-I13))))) -> 2.6548271 | H13: =RAND() -> 0.351716 | I13: =('Tesla Valuation Inputs'!D13-'Tesla Valuation Inputs'!C13)/2+'Tesla Valuation Inputs'!C13 -> 2.75
A14: Balance sheet assumptions | B14: Minimum | C14: Downside | D14: Upside | E14: Maximum
A15: Percent of factory-build/internal fleet that will be debt funded | B15: 0 | C15: 0.1 | D15: 0.15 | E15: 0.2 | G15: =IF(I15=D15,I15,IF(_xlfn.NORM.INV(H15,I15,(D15-I15))<B15,B15,IF(_xlfn.NORM.INV(H15,I15,(D15-I15))>E15,E15,_xlfn.NORM.INV(H15,I15,(D15-I15))))) -> 0.15850238 | H15: =RAND() -> 0.90989281 | I15: =('Tesla Valuation Inputs'!D15-'Tesla Valuation Inputs'!C15)/2+'Tesla Valuation Inputs'!C15 -> 0.125
A16: Vehicle capital efficiency 2031 (gross capex per vehicle produced, not in millions) | B16: 2000 | C16: 5000 | D16: 7000 | E16: 14000 | G16: =IF(I16=D16,I16,IF(_xlfn.NORM.INV(H16,I16,(D16-I16))<B16,B16,IF(_xlfn.NORM.INV(H16,I16,(D16-I16))>E16,E16,_xlfn.NORM.INV(H16,I16,(D16-I16))))) -> 6348.8086 | H16: =RAND() -> 0.6363835 | I16: =('Tesla Valuation Inputs'!D16-'Tesla Valuation Inputs'!C16)/2+'Tesla Valuation Inputs'!C16 -> 6000
A17: % of Year-end cash that's dedicated to AI Infrastructure and Chip Development | B17: 0.1 | C17: 0.15 | D17: 0.2 | E17: 0.25 | G17: =IF(I17=D17,I17,IF(_xlfn.NORM.INV(H17,I17,(D17-I17))<B17,B17,IF(_xlfn.NORM.INV(H17,I17,(D17-I17))>E17,E17,_xlfn.NORM.INV(H17,I17,(D17-I17))))) -> 0.14541062 | H17: =RAND() -> 0.11829064 | I17: =('Tesla Valuation Inputs'!D17-'Tesla Valuation Inputs'!C17)/2+'Tesla Valuation Inputs'!C17 -> 0.175
A18: Bitcoin price appreciation (depreciation) annual | B18: -0.5 | C18: -0.3 | D18: 0.5 | E18: 1 | G18: =IF(I18=D18,I18,IF(_xlfn.NORM.INV(H18,I18,(D18-I18))<B18,B18,IF(_xlfn.NORM.INV(H18,I18,(D18-I18))>E18,E18,_xlfn.NORM.INV(H18,I18,(D18-I18))))) -> -0.12771641 | H18: =RAND() -> 0.28457932 | I18: =('Tesla Valuation Inputs'!D18-'Tesla Valuation Inputs'!C18)/2+'Tesla Valuation Inputs'!C18 -> 0.1
A19: Weighted average market capitalization at which equity is raised (millions) | B19: 700000 | C19: 1000000 | D19: 2000000 | E19: 3000000 | G19: =IF(I19=D19,I19,IF(_xlfn.NORM.INV(H19,I19,(D19-I19))<B19,B19,IF(_xlfn.NORM.INV(H19,I19,(D19-I19))>E19,E19,_xlfn.NORM.INV(H19,I19,(D19-I19))))) -> 1846881.4 | H19: =RAND() -> 0.75608454 | I19: =('Tesla Valuation Inputs'!D19-'Tesla Valuation Inputs'!C19)/2+'Tesla Valuation Inputs'!C19 -> 1500000
A20: Equity raise for capex (millions) | B20: 0 | C20: 0 | D20: 0 | E20: 0 | G20: =IF(I20=D20,I20,IF(_xlfn.NORM.INV(H20,I20,(D20-I20))<B20,B20,IF(_xlfn.NORM.INV(H20,I20,(D20-I20))>E20,E20,_xlfn.NORM.INV(H20,I20,(D20-I20))))) -> 0 | H20: =RAND() -> 0.88060379 | I20: =('Tesla Valuation Inputs'!D20-'Tesla Valuation Inputs'!C20)/2+'Tesla Valuation Inputs'!C20 -> 0
A21: Margin Assumptions | B21: Minimum | C21: Downside | D21: Upside | E21: Maximum
A22: Max gross margin on vehicle sales | B22: 0.125 | C22: 0.2 | D22: 0.3 | E22: 0.5 | G22: =IF(I22=D22,I22,IF(_xlfn.NORM.INV(H22,I22,(D22-I22))<B22,B22,IF(_xlfn.NORM.INV(H22,I22,(D22-I22))>E22,E22,_xlfn.NORM.INV(H22,I22,(D22-I22))))) -> 0.28066579 | H22: =RAND() -> 0.73016622 | I22: =('Tesla Valuation Inputs'!D22-'Tesla Valuation Inputs'!C22)/2+'Tesla Valuation Inputs'!C22 -> 0.25
A23: Wright's Law learning rate | B23: 0.1 | C23: 0.14 | D23: 0.17 | E23: 0.2 | F23: For more on Wright's Law, see: https://ark-invest.com/wrights-law/ | G23: =IF(I23=D23,I23,IF(_xlfn.NORM.INV(H23,I23,(D23-I23))<B23,B23,IF(_xlfn.NORM.INV(H23,I23,(D23-I23))>E23,E23,_xlfn.NORM.INV(H23,I23,(D23-I23))))) -> 0.16553012 | H23: =RAND() -> 0.758663 | I23: =('Tesla Valuation Inputs'!D23-'Tesla Valuation Inputs'!C23)/2+'Tesla Valuation Inputs'!C23 -> 0.155
A24: Electric Vehicle factory utilization factor | B24: 0.7 | C24: 0.7 | D24: 0.9 | E24: 0.95 | G24: =IF(I24=D24,I24,IF(_xlfn.NORM.INV(H24,I24,(D24-I24))<B24,B24,IF(_xlfn.NORM.INV(H24,I24,(D24-I24))>E24,E24,_xlfn.NORM.INV(H24,I24,(D24-I24))))) -> 0.7 | H24: =RAND() -> 0.031964554 | I24: =('Tesla Valuation Inputs'!D24-'Tesla Valuation Inputs'!C24)/2+'Tesla Valuation Inputs'!C24 -> 0.8
A25: Percent of each model/price segment that Tesla penetrates | B25: 0.05 | C25: 0.075 | D25: 0.125 | E25: 0.2 | G25: =IF(I25=D25,I25,IF(_xlfn.NORM.INV(H25,I25,(D25-I25))<B25,B25,IF(_xlfn.NORM.INV(H25,I25,(D25-I25))>E25,E25,_xlfn.NORM.INV(H25,I25,(D25-I25))))) -> 0.068013237 | H25: =RAND() -> 0.1003657 | I25: =('Tesla Valuation Inputs'!D25-'Tesla Valuation Inputs'!C25)/2+'Tesla Valuation Inputs'!C25 -> 0.1
A26: Tax rate | B26: 0.15 | C26: 0.175 | D26: 0.225 | E26: 0.25 | G26: =IF(I26=D26,I26,IF(_xlfn.NORM.INV(H26,I26,(D26-I26))<B26,B26,IF(_xlfn.NORM.INV(H26,I26,(D26-I26))>E26,E26,_xlfn.NORM.INV(H26,I26,(D26-I26))))) -> 0.21258129 | H26: =RAND() -> 0.69260628 | I26: =('Tesla Valuation Inputs'!D26-'Tesla Valuation Inputs'!C26)/2+'Tesla Valuation Inputs'!C26 -> 0.2
A27: Interest rate | B27: 0.02 | C27: 0.04 | D27: 0.06 | E27: 0.06 | G27: =IF(I27=D27,I27,IF(_xlfn.NORM.INV(H27,I27,(D27-I27))<B27,B27,IF(_xlfn.NORM.INV(H27,I27,(D27-I27))>E27,E27,_xlfn.NORM.INV(H27,I27,(D27-I27))))) -> 0.034487119 | H27: =RAND() -> 0.060416326 | I27: =('Tesla Valuation Inputs'!D27-'Tesla Valuation Inputs'!C27)/2+'Tesla Valuation Inputs'!C27 -> 0.05
A28: EBITDA As A % of Gross Margin - Electric Vehicle | B28: 0.6 | C28: 0.65 | D28: 0.75 | E28: 0.8 | G28: =IF(I28=D28,I28,IF(_xlfn.NORM.INV(H28,I28,(D28-I28))<B28,B28,IF(_xlfn.NORM.INV(H28,I28,(D28-I28))>E28,E28,_xlfn.NORM.INV(H28,I28,(D28-I28))))) -> 0.77597188 | H28: =RAND() -> 0.93567381 | I28: =('Tesla Valuation Inputs'!D28-'Tesla Valuation Inputs'!C28)/2+'Tesla Valuation Inputs'!C28 -> 0.7
A29: EBITDA As A % of Gross Margin - Stationary Energy Storage | B29: 0.65 | C29: 0.675 | D29: 0.775 | E29: 0.8 | G29: =IF(I29=D29,I29,IF(_xlfn.NORM.INV(H29,I29,(D29-I29))<B29,B29,IF(_xlfn.NORM.INV(H29,I29,(D29-I29))>E29,E29,_xlfn.NORM.INV(H29,I29,(D29-I29))))) -> 0.70984475 | H29: =RAND() -> 0.38090494 | I29: =('Tesla Valuation Inputs'!D29-'Tesla Valuation Inputs'!C29)/2+'Tesla Valuation Inputs'!C29 -> 0.725
A30: EBITDA As A % of Gross Margin - Optimus Hardware Sales | B30: 0.7 | C30: 0.7 | D30: 0.8 | E30: 0.8 | G30: =IF(I30=D30,I30,IF(_xlfn.NORM.INV(H30,I30,(D30-I30))<B30,B30,IF(_xlfn.NORM.INV(H30,I30,(D30-I30))>E30,E30,_xlfn.NORM.INV(H30,I30,(D30-I30))))) -> 0.8 | H30: =RAND() -> 0.86727881 | I30: =('Tesla Valuation Inputs'!D30-'Tesla Valuation Inputs'!C30)/2+'Tesla Valuation Inputs'!C30 -> 0.75
A31: EBITDA As A % of Gross Margin - Optimus RaaS | B31: 0.7 | C31: 0.75 | D31: 0.85 | E31: 0.9 | G31: =IF(I31=D31,I31,IF(_xlfn.NORM.INV(H31,I31,(D31-I31))<B31,B31,IF(_xlfn.NORM.INV(H31,I31,(D31-I31))>E31,E31,_xlfn.NORM.INV(H31,I31,(D31-I31))))) -> 0.79953231 | H31: =RAND() -> 0.4962684 | I31: =('Tesla Valuation Inputs'!D31-'Tesla Valuation Inputs'!C31)/2+'Tesla Valuation Inputs'!C31 -> 0.8
A32: Autonomous Assumptions | B32: Minimum | C32: Downside | D32: Upside | E32: Maximum
A33: Percent of customer owned fleet in China | B33: 0.2 | C33: 0.3 | D33: 0.4 | E33: 0.5 | G33: =IF(I33=D33,I33,IF(_xlfn.NORM.INV(H33,I33,(D33-I33))<B33,B33,IF(_xlfn.NORM.INV(H33,I33,(D33-I33))>E33,E33,_xlfn.NORM.INV(H33,I33,(D33-I33))))) -> 0.37694604 | H33: =RAND() -> 0.70502927 | I33: =('Tesla Valuation Inputs'!D33-'Tesla Valuation Inputs'!C33)/2+'Tesla Valuation Inputs'!C33 -> 0.35
A34: Maximum robotaxis Tesla will own & operate itself (not in millions) | B34: 2000 | C34: 3000 | D34: 4000 | E34: 5000 | G34: =IF(I34=D34,I34,IF(_xlfn.NORM.INV(H34,I34,(D34-I34))<B34,B34,IF(_xlfn.NORM.INV(H34,I34,(D34-I34))>E34,E34,_xlfn.NORM.INV(H34,I34,(D34-I34))))) -> 3443.1085 | H34: =RAND() -> 0.45470494 | I34: =('Tesla Valuation Inputs'!D34-'Tesla Valuation Inputs'!C34)/2+'Tesla Valuation Inputs'!C34 -> 3500
A35: Stationary Energy Storage Assumptions | B35: Minimum | C35: Downside | D35: Upside | E35: Maximum
A36: Stationary energy storage capital efficiency 2031 (gross capex per MWh deployed, not in millions) | B36: 5000 | C36: 6000 | D36: 8000 | E36: 10000 | G36: =IF(I36=D36,I36,IF(_xlfn.NORM.INV(H36,I36,(D36-I36))<B36,B36,IF(_xlfn.NORM.INV(H36,I36,(D36-I36))>E36,E36,_xlfn.NORM.INV(H36,I36,(D36-I36))))) -> 7981.6733 | H36: =RAND() -> 0.8368696 | I36: =('Tesla Valuation Inputs'!D36-'Tesla Valuation Inputs'!C36)/2+'Tesla Valuation Inputs'!C36 -> 7000
A37: Max annual energy increase (given management bandwidth constraints) | B37: 0.4 | C37: 0.8 | D37: 1 | E37: 1.2 | G37: =IF(I37=D37,I37,IF(_xlfn.NORM.INV(H37,I37,(D37-I37))<B37,B37,IF(_xlfn.NORM.INV(H37,I37,(D37-I37))>E37,E37,_xlfn.NORM.INV(H37,I37,(D37-I37))))) -> 0.98115305 | H37: =RAND() -> 0.79146947 | I37: =('Tesla Valuation Inputs'!D37-'Tesla Valuation Inputs'!C37)/2+'Tesla Valuation Inputs'!C37 -> 0.9
A38: Gross margin of stationary energy storage business in 2031 | B38: 0.1 | C38: 0.2 | D38: 0.3 | E38: 0.4 | G38: =IF(I38=D38,I38,IF(_xlfn.NORM.INV(H38,I38,(D38-I38))<B38,B38,IF(_xlfn.NORM.INV(H38,I38,(D38-I38))>E38,E38,_xlfn.NORM.INV(H38,I38,(D38-I38))))) -> 0.24214251 | H38: =RAND() -> 0.43756337 | I38: =('Tesla Valuation Inputs'!D38-'Tesla Valuation Inputs'!C38)/2+'Tesla Valuation Inputs'!C38 -> 0.25
A39: Optimus Assumptions | B39: Minimum | C39: Downside | D39: Upside | E39: Maximum
A40: Optimus Capability Increase For Every Cumulative Doubling in AI Spend | B40: 0.05 | C40: 0.1 | D40: 0.15 | E40: 0.2 | G40: =IF(I40=D40,I40,IF(_xlfn.NORM.INV(H40,I40,(D40-I40))<B40,B40,IF(_xlfn.NORM.INV(H40,I40,(D40-I40))>E40,E40,_xlfn.NORM.INV(H40,I40,(D40-I40))))) -> 0.10423006 | H40: =RAND() -> 0.203044 | I40: =('Tesla Valuation Inputs'!D40-'Tesla Valuation Inputs'!C40)/2+'Tesla Valuation Inputs'!C40 -> 0.125
A41: What year does Tesla begin selling Optimi externally? | B41: 2027 | C41: 2027 | D41: 2029 | E41: 2030 | G41: =ROUND(IF(I41=D41,I41,IF(_xlfn.NORM.INV(H41,I41,(D41-I41))<B41,B41,IF(_xlfn.NORM.INV(H41,I41,(D41-I41))>E41,E41,_xlfn.NORM.INV(H41,I41,(D41-I41))))),0) -> 2029 | H41: =RAND() -> 0.82819471 | I41: =('Tesla Valuation Inputs'!D41-'Tesla Valuation Inputs'!C41)/2+'Tesla Valuation Inputs'!C41 -> 2028
A42: Once available for external use - what % of Optimi production does Tesla dedicate to in-house use up until the cap is reached? | B42: 0 | C42: 0.05 | D42: 0.1 | E42: 0.2 | G42: =IF(I42=D42,I42,IF(_xlfn.NORM.INV(H42,I42,(D42-I42))<B42,B42,IF(_xlfn.NORM.INV(H42,I42,(D42-I42))>E42,E42,_xlfn.NORM.INV(H42,I42,(D42-I42))))) -> 0.03430329 | H42: =RAND() -> 0.051776398 | I42: =('Tesla Valuation Inputs'!D42-'Tesla Valuation Inputs'!C42)/2+'Tesla Valuation Inputs'!C42 -> 0.075
A43: Maximum Optimi deployed in the factory | B43: 13500 | C43: 67500 | D43: 135000 | E43: 270000 | G43: =IF(I43=D43,I43,IF(_xlfn.NORM.INV(H43,I43,(D43-I43))<B43,B43,IF(_xlfn.NORM.INV(H43,I43,(D43-I43))>E43,E43,_xlfn.NORM.INV(H43,I43,(D43-I43))))) -> 75885.943 | H43: =RAND() -> 0.22616759 | I43: =('Tesla Valuation Inputs'!D43-'Tesla Valuation Inputs'!C43)/2+'Tesla Valuation Inputs'!C43 -> 101250
...

Sheet Valuation ASP Tables
A1: Valuation ASP Tables
A2: Blue text indicates assumptions that can be altered, altering one input may require altering another input in order to get reasonable results
A3: Black text indicates cells with formulas or cells with static values that are not meant to be altered
A5: Electric Vehicle ASP Table
A6: Model | B6: Global ASP | C6: TAM units in segment | D6: Max units Tesla | E6: Cumulative units | F6: Market Segments | G6: Cumulative Market Size At Each Segment | H6: Notes
A7: Micromobility EV | B7: 7000 | C7: 1000000000000 | D7: =$C7*'Monte Carlo Single Simulation'!$N$25 -> 6.8013237e+10 | E7: =D7+E8 -> 6.8025402e+10 | F7: =B7*D7 -> 4.7609266e+14 | G7: =F7+G8 -> 4.7639284e+14 | H7: Note, top bucket is nominally large to prevent formula error in rare scenarios.
A8: Neighborhood EV | B8: 15000 | C8: 100000000 | D8: =$C8*'Monte Carlo Single Simulation'!$N$25 -> 6801323.7 | E8: =D8+E9 -> 12165363 | F8: =B8*D8 -> 1.0201985e+11 | G8: =F8+G9 -> 3.0018291e+11
A9: Cybercab | B9: 25000 | C9: 41000000 | D9: =$C9*'Monte Carlo Single Simulation'!$N$25 -> 2788542.7 | E9: =D9+E10 -> 5364039.1 | F9: =B9*D9 -> 6.9713568e+10 | G9: =F9+G10 -> 1.9816306e+11
A10: Cybertruck | B10: 80000 | C10: 1500000 | D10: =$C10*'Monte Carlo Single Simulation'!$N$25 -> 102019.85 | E10: =D10+E11 -> 2575496.4 | F10: =B10*D10 -> 8.1615884e+09 | G10: =F10+G11 -> 1.2844949e+11
A11: Model Y | B11: 50000 | C11: 22000000 | D11: =$C11*'Monte Carlo Single Simulation'!$N$25 -> 1496291.2 | E11: =D11+E12 -> 2473476.5 | F11: =B11*D11 -> 7.481456e+10 | G11: =F11+G12 -> 1.202879e+11
A12: Model 3 | B12: 45000 | C12: 14000000 | D12: =$C12*'Monte Carlo Single Simulation'!$N$25 -> 952185.31 | E12: =D12+E13 -> 977185.31 | F12: =B12*D12 -> 4.2848339e+10 | G12: =F12+G13 -> 4.5473339e+10
A13: S/X | B13: 105000 | C13: 25000 | D13: 25000 | E13: =D13 -> 25000 | F13: =B13*D13 -> 2625000000 | G13: =F13 -> 2625000000 | H13: Model S/X hardcoded to roughly match 2026 sales; retired from 2027 onwards (excluded from the ASP calculation).
A15: Graph Inputs | C15: Note: This adoption curve is used to assign eligible cars to the robotaxi fleet.
A16: Base Year | B16: 0
A17: Saturation Percentage | B17: 100
A18: Start of Fast Growth | B18: 3
A19: Take Over Time | B19: ='Monte Carlo Single Simulation'!N12 -> 5.2343191
A21: Year | B21: Penetration
A22: 0 | B22: =$B$17/(1+POWER(81,($B$18+$B$19/2-A22)/$B$19))*(1/100) -> 0.0088727235
A23: =A22+1 -> 1 | B23: =$B$17/(1+POWER(81,($B$18+$B$19/2-A23)/$B$19))*(1/100) -> 0.020306164
A24: =A23+1 -> 2 | B24: =$B$17/(1+POWER(81,($B$18+$B$19/2-A24)/$B$19))*(1/100) -> 0.045792095
A25: =A24+1 -> 3 | B25: =$B$17/(1+POWER(81,($B$18+$B$19/2-A25)/$B$19))*(1/100) -> 0.1
A26: =A25+1 -> 4 | B26: =$B$17/(1+POWER(81,($B$18+$B$19/2-A26)/$B$19))*(1/100) -> 0.20461778
A27: =A26+1 -> 5 | B27: =$B$17/(1+POWER(81,($B$18+$B$19/2-A27)/$B$19))*(1/100) -> 0.37328878
A28: =A27+1 -> 6 | B28: =$B$17/(1+POWER(81,($B$18+$B$19/2-A28)/$B$19))*(1/100) -> 0.57966833
A29: =A28+1 -> 7 | B29: =$B$17/(1+POWER(81,($B$18+$B$19/2-A29)/$B$19))*(1/100) -> 0.76150666
A30: =A29+1 -> 8 | B30: =$B$17/(1+POWER(81,($B$18+$B$19/2-A30)/$B$19))*(1/100) -> 0.88084989
A31: =A30+1 -> 9 | B31: =$B$17/(1+POWER(81,($B$18+$B$19/2-A31)/$B$19))*(1/100) -> 0.944802
A32: =A31+1 -> 10 | B32: =$B$17/(1+POWER(81,($B$18+$B$19/2-A32)/$B$19))*(1/100) -> 0.97538783
A33: =A32+1 -> 11 | B33: =$B$17/(1+POWER(81,($B$18+$B$19/2-A33)/$B$19))*(1/100) -> 0.9892191
A34: =A33+1 -> 12 | B34: =$B$17/(1+POWER(81,($B$18+$B$19/2-A34)/$B$19))*(1/100) -> 0.99531496
... A37: =A36+1 -> 15 | B37: =$B$17/(1+POWER(81,($B$18+$B$19/2-A37)/$B$19))*(1/100) -> 0.9996209
A40: Note the lowest price mileage bucket is inflated to catch any overfall in cases of extreme growth within the Monte Carlo
A41: Ride-hail ASP Table | L41: Decile Inputs (constant across all years) | P41: Cost Inputs by Year ($/mi, constant across deciles)
A42: Year | B42: Price Decile | C42: Metro Miles | D42: Cumulative Metro Miles | E42: Price Per Mile | F42: Price Market Segments | G42: Cumulative Price Market Size | H42: Fleet Owner Fee | I42: Platform Operator COGS | J42: Platform Operator Overhead | L42: Price Decile | M42: Cohort Miles (bn) | N42: Cohort Price $/mi | P42: Year | Q42: Fleet Owner Fee | R42: Platform Operator COGS | S42: Platform Operator OH
A43: {=INDEX($P$43:$P$57,INT((ROW()-43)/10)+1)} -> 2026 | B43: {=INDEX($L$43:$L$52,MOD(ROW()-43,10)+1)} -> D1 | C43: =_xlfn.XLOOKUP($B43,$L$43:$L$52,$M$43:$M$52)*10^9 -> 200000000000000 | D43: =C43+D44 -> 202371100000000 | E43: =_xlfn.XLOOKUP($B43,$L$43:$L$52,$N$43:$N$52) -> 0.443 | F43: =C43*E43 -> 88600000000000 | G43: =F43+G44 -> 91099582600000 | H43: =_xlfn.XLOOKUP($A43,$P$43:$P$57,$Q$43:$Q$57) -> 0.33168904 | I43: =_xlfn.XLOOKUP($A43,$P$43:$P$57,$R$43:$R$57) -> 0.24 | J43: =_xlfn.XLOOKUP($A43,$P$43:$P$57,$S$43:$S$57) -> 0.11 | L43: D1 | M43: 200000 | N43: 0.443 | O43: Note, D1 bucket is overflow to prevent formulae error. | P43: 2026 | Q43: 0.33168904 | R43: 0.24 | S43: 0.11
A44: {=INDEX($P$43:$P$57,INT((ROW()-43)/10)+1)} -> 2026 | B44: {=INDEX($L$43:$L$52,MOD(ROW()-43,10)+1)} -> D2 | C44: =_xlfn.XLOOKUP($B44,$L$43:$L$52,$M$43:$M$52)*10^9 -> 186000000000 | D44: =C44+D45 -> 2371100000000 | E44: =_xlfn.XLOOKUP($B44,$L$43:$L$52,$N$43:$N$52) -> 0.537 | F44: =C44*E44 -> 99882000000 | G44: =F44+G45 -> 2499582600000 | H44: =_xlfn.XLOOKUP($A44,$P$43:$P$57,$Q$43:$Q$57) -> 0.33168904 | I44: =_xlfn.XLOOKUP($A44,$P$43:$P$57,$R$43:$R$57) -> 0.24 | J44: =_xlfn.XLOOKUP($A44,$P$43:$P$57,$S$43:$S$57) -> 0.11 | L44: D2 | M44: 186 | N44: 0.537 | P44: 2027 | Q44: 0.21610846 | R44: 0.16 | S44: 0.09
A45: {=INDEX($P$43:$P$57,INT((ROW()-43)/10)+1)} -> 2026 | B45: {=INDEX($L$43:$L$52,MOD(ROW()-43,10)+1)} -> D3 | C45: =_xlfn.XLOOKUP($B45,$L$43:$L$52,$M$43:$M$52)*10^9 -> 205000000000 | D45: =C45+D46 -> 2185100000000 | E45: =_xlfn.XLOOKUP($B45,$L$43:$L$52,$N$43:$N$52) -> 0.624 | F45: =C45*E45 -> 127920000000 | G45: =F45+G46 -> 2399700600000 | H45: =_xlfn.XLOOKUP($A45,$P$43:$P$57,$Q$43:$Q$57) -> 0.33168904 | I45: =_xlfn.XLOOKUP($A45,$P$43:$P$57,$R$43:$R$57) -> 0.24 | J45: =_xlfn.XLOOKUP($A45,$P$43:$P$57,$S$43:$S$57) -> 0.11 | L45: D3 | M45: 205 | N45: 0.624 | P45: 2028 | Q45: 0.19701344 | R45: 0.11 | S45: 0.08
A46: {=INDEX($P$43:$P$57,INT((ROW()-43)/10)+1)} -> 2026 | B46: {=INDEX($L$43:$L$52,MOD(ROW()-43,10)+1)} -> D4 | C46: =_xlfn.XLOOKUP($B46,$L$43:$L$52,$M$43:$M$52)*10^9 -> 219300000000 | D46: =C46+D47 -> 1980100000000 | E46: =_xlfn.XLOOKUP($B46,$L$43:$L$52,$N$43:$N$52) -> 0.699 | F46: =C46*E46 -> 153290700000 | G46: =F46+G47 -> 2271780600000 | H46: =_xlfn.XLOOKUP($A46,$P$43:$P$57,$Q$43:$Q$57) -> 0.33168904 | I46: =_xlfn.XLOOKUP($A46,$P$43:$P$57,$R$43:$R$57) -> 0.24 | J46: =_xlfn.XLOOKUP($A46,$P$43:$P$57,$S$43:$S$57) -> 0.11 | L46: D4 | M46: 219.3 | N46: 0.699 | P46: 2029 | Q46: 0.1903348 | R46: 0.07 | S46: 0.07
A47: {=INDEX($P$43:$P$57,INT((ROW()-43)/10)+1)} -> 2026 | B47: {=INDEX($L$43:$L$52,MOD(ROW()-43,10)+1)} -> D5 | C47: =_xlfn.XLOOKUP($B47,$L$43:$L$52,$M$43:$M$52)*10^9 -> 238500000000 | D47: =C47+D48 -> 1760800000000 | E47: =_xlfn.XLOOKUP($B47,$L$43:$L$52,$N$43:$N$52) -> 0.798 | F47: =C47*E47 -> 190323000000 | G47: =F47+G48 -> 2118489900000 | H47: =_xlfn.XLOOKUP($A47,$P$43:$P$57,$Q$43:$Q$57) -> 0.33168904 | I47: =_xlfn.XLOOKUP($A47,$P$43:$P$57,$R$43:$R$57) -> 0.24 | J47: =_xlfn.XLOOKUP($A47,$P$43:$P$57,$S$43:$S$57) -> 0.11 | L47: D5 | M47: 238.5 | N47: 0.798 | P47: 2030 | Q47: 0.18544418 | R47: 0.06 | S47: 0.06
...

Sheet Monte Carlo Single Simulation
A1: Monte Carlo Single Simulation
A2: Blue text indicates assumptions that can be altered; altering one input may require altering another input in order to get reasonable results.
A3: Black text indicates cells with formulas or cells with static values that are not meant to be altered.
A4: Note: To utilize the Monte Carlo, you need to use the "Calculate Now" button in excel, not "Calculate Sheet".
A5: Values are in millions unless otherwise specified except for per share amounts, multiples, and ratios. | H5: Results Box
H6: 2031 Suggested Share Price | N6: =N180 -> 3923.8198
H7: CAGR | N7: =N182 -> 0.58603625
B8: 2019 | C8: =B8+1 -> 2020 | D8: =C8+1 -> 2021 | E8: =D8+1 -> 2022 | F8: =E8+1 -> 2023 | G8: =F8+1 -> 2024 | H8: =G8+1 -> 2025 | I8: =H8+1 -> 2026 | J8: =I8+1 -> 2027 | ... N8: =M8+1 -> 2031 | AA8: Notes
A9: Key Drivers
A10: Max annual vehicle production increase (given management bandwidth constraints) | N10: ='Tesla Valuation Inputs'!G10 -> 0.40507328 | AA10: Provides an upper bound for vehicle production to accommodate management bandwidth constraints in building out factories.
A11: Miles traveled per robotaxi (not in millions) | N11: ='Tesla Valuation Inputs'!G11 -> 74200.303 | AA11: Elon Musk has previously stated that a robotaxi could have ~5-6x greater utilization than human-driven vehicle (~11,000 miles per year).
A12: Takeover time for autonomous adoption (years between 10% and 90% market saturation) | N12: ='Tesla Valuation Inputs'!G12 -> 5.2343191 | AA12: Time from 10% to 90% saturation
A13: Max annual Optimi production increase (given management bandwidth constraints) | N13: ='Tesla Valuation Inputs'!G13 -> 2.6548271 | AA13: Provides an upper bound for Optimus production to accommodate management bandwidth constraints in building out factories.
A14: Balance sheet assumptions
A15: Percent of factory-build/internal fleet that will be debt funded | N15: ='Tesla Valuation Inputs'!G15 -> 0.15850238 | AA15: Determines how much debt Tesla raises as it scales
A16: Vehicle capital efficiency 2031 (gross capex per vehicle produced, not in millions) | N16: ='Tesla Valuation Inputs'!G16 -> 6348.8086 | O16: Floor: | P16: 1800 | Q16: Ceiling: | R16: 15400 | AA16: The cost per vehicle of new production capacity. Lower = more efficient
A17: % of Year-end cash that's dedicated to AI Infrastructure and Chip Development | N17: ='Tesla Valuation Inputs'!G17 -> 0.14541062 | AA17: % of Year-end cash that goes towards AI infrastructure and Chip Development
A18: Bitcoin price appreciation (depreciation) annual | N18: ='Tesla Valuation Inputs'!G18 -> -0.12771641 | AA18: Bitcoin price appreciation (depreciation) annual. For more information on ARK's bitcoin research, see https://www.ark-invest.com/big-ideas-2026
A19: Weighted average market capitalization at which equity is raised (millions) | N19: ='Tesla Valuation Inputs'!G19 -> 1846881.4 | AA19: For simplicity, assume all Tesla equity raise occurs at this valuation. Note as modeled, this is not used, however users can change the Monte Carlo inputs to activate this line.
A20: Equity raise for capex (millions) | N20: ='Tesla Valuation Inputs'!G20 -> 0 | AA20: Assumption on Tesla Equity raise over the next five years. Note as modeled, this is not used, however users can change the Monte Carlo inputs to activate this line.
A21: Margin Assumptions
A22: Max gross margin on vehicle sales | N22: ='Tesla Valuation Inputs'!G22 -> 0.28066579 | AA22: Gross margin is driven by Wright's Law. This input is the max gross margin that the model allows Tesla to achieve. For more on Wright's Law, see: https://ark-invest.com/wrights-law/
A23: Wright's Law learning rate | N23: ='Tesla Valuation Inputs'!G23 -> 0.16553012 | AA23: The percent cost decline for every cumulative doubling of production.
A24: Electric Vehicle factory utilization factor | N24: ='Tesla Valuation Inputs'!G24 -> 0.7 | AA24: This is based on Tesla's historical utilization rates. Applied uniformly across all years.
A25: Percent of each model/price segment that Tesla penetrates | N25: ='Tesla Valuation Inputs'!G25 -> 0.068013237 | AA25: See ASP Tables tab. Provides an upper bound for addressable market within each vehicle segment.
A26: Tax rate | N26: ='Tesla Valuation Inputs'!G26 -> 0.21258129 | AA26: Tax rate applied to profits.
A27: Interest rate | N27: ='Tesla Valuation Inputs'!G27 -> 0.034487119 | AA27: Applied uniformly across all years for simplicity
A28: EBITDA As A % of Gross Margin - Electric Vehicle | N28: ='Tesla Valuation Inputs'!G28 -> 0.77597188 | AA28: EBITDA as a % of Gross Margin for the EV business.
A29: EBITDA As A % of Gross Margin - Stationary Energy Storage | N29: ='Tesla Valuation Inputs'!G29 -> 0.70984475 | AA29: EBITDA as a % of Gross Margin for the Stationary Energy Storage business.
A30: EBITDA As A % of Gross Margin - Optimus Hardware Sales | N30: ='Tesla Valuation Inputs'!G30 -> 0.8 | AA30: EBITDA as a % of Gross Margin for external Optimus hardware sales.
A31: EBITDA As A % of Gross Margin - Optimus RaaS | N31: ='Tesla Valuation Inputs'!G31 -> 0.79953231 | AA31: EBITDA as a % of Gross Margin for the Optimus Robot-as-a-Service (software subscription) business.
A32: Autonomous Assumptions
A33: Percent of customer owned fleet in China | N33: ='Tesla Valuation Inputs'!G33 -> 0.37694604 | AA33: What % of Tesla's Fleet is in China
A34: Maximum robotaxis Tesla will own & operate itself (not in millions) | N34: ='Tesla Valuation Inputs'!G34 -> 3443.1085 | AA34: This is a cap applied to the maximum number of robotaxis that Tesla will own and operate before partnering.
A35: Stationary Energy Storage Assumptions
A36: Stationary energy storage capital efficiency 2031 (gross capex per MWh deployed, not in millions) | N36: ='Tesla Valuation Inputs'!G36 -> 7981.6733 | O36: Floor: | P36: 4500 | Q36: Ceiling: | R36: 11000 | AA36: The cost per MWh deployed of new production capacity. Lower = more efficient
A37: Max annual energy increase (given management bandwidth constraints) | N37: ='Tesla Valuation Inputs'!G37 -> 0.98115305 | AA37: Provides an upper bound for energy production to accommodate management bandwidth constraints in building out factories.
A38: Gross margin of stationary energy storage business in 2031 | N38: ='Tesla Valuation Inputs'!G38 -> 0.24214251 | O38: Floor: | P38: 0.09 | Q38: Ceiling: | R38: 0.44 | AA38: This is the gross margin that will be applied to the stationary energy business in 2031. CAGR to this value from 2025.
A39: Optimus Assumptions
A40: Optimus Capability Increase For Every Cumulative Doubling in AI Spend | N40: ='Tesla Valuation Inputs'!G40 -> 0.10423006 | AA40: For every cumulative doubling in compute spend, Optimus performance will increase by this percent.
...

Sheet Monte Carlo Simulation Output
A1: Monte Carlo Simulation Output
A2: This worksheet contains extracts from all simulations. Note that the workbook may take a minute to calculate.
A3: Note: To utilize the Monte Carlo, you need to use the "Calculate Now" button in excel, not "Calculate Sheet".
A5: Monte Carlo | B5: 2031 Electric Vehicles Sold | C5: 2031 Cumulative Robotaxi Fleet | D5: 2031 Optimus Cumulatively Deployed Externally | E5: 2031 Cumulative Storage Deployed | F5: 2031 Cumulative AI Infrastructure Spend | G5: 2031 Outstanding Debt | H5: 2031 Enterprise Value For Electric Vehicles | I5: 2031 Enterprise Value For Robotaxi | J5: 2031 Enterprise Value For Stationary Energy Storage | K5: 2031 Enterprise Value For External Optimi Sales | L5: 2031 Enterprise Value For Robot-as-a-Service (RaaS) | M5: 2031 Enterprise Value | N5: 2031 Market Cap | O5: 2031 EBITDA Margin | P5: 2031 Gross Margin | Q5: 2031 Share Price | R5: 2031 Optimus Capability (% of Human-Level Productivity)
A6: 1 | B6: ='Monte Carlo Single Simulation'!N86 -> 8912560.4 | C6: ='Monte Carlo Single Simulation'!N101 -> 6343476.2 | D6: ='Monte Carlo Single Simulation'!N142 -> 849214.43 | E6: =SUM('Monte Carlo Single Simulation'!B121:N121) -> 5715458.6 | F6: ='Monte Carlo Single Simulation'!N70 -> 1.9294861e+11 | G6: ='Monte Carlo Single Simulation'!N83 -> 6.3115745e+10 | H6: ='Monte Carlo Single Simulation'!N172 -> 3.2255754e+11 | I6: ='Monte Carlo Single Simulation'!N173 -> 1.2442405e+13 | J6: ='Monte Carlo Single Simulation'!N174 -> 3.4794244e+11 | K6: ='Monte Carlo Single Simulation'!N175 -> 8.6870976e+10 | L6: ='Monte Carlo Single Simulation'!N176 -> 1.7091895e+12 | M6: ='Monte Carlo Single Simulation'!N177 -> 1.4908965e+13 | N6: ='Monte Carlo Single Simulation'!N178 -> 1.5907165e+13 | O6: ='Monte Carlo Single Simulation'!N166 -> 0.61953002 | P6: ='Monte Carlo Single Simulation'!N165 -> 0.67680115 | Q6: ='Monte Carlo Single Simulation'!N180 -> 3923.8198 | R6: ='Monte Carlo Single Simulation'!N136 -> 0.96790757
A7: =A6+1 -> 2 | B7: 12744347 | C7: 11036434 | D7: 841964.9 | E7: 5788644.8 | F7: 2.4686325e+11 | G7: 5.9165017e+10 | H7: 5.9982748e+11 | I7: 1.5741047e+13 | J7: 3.516437e+11 | K7: 8.9675434e+10 | L7: 2.7491009e+12 | M7: 1.9531294e+13 | N7: 2.0859193e+13 | O7: 0.62322869 | P7: 0.68095153 | Q7: 5145.3363 | R7: 1.4786875
A8: =A7+1 -> 3 | B8: 12011879 | C8: 10873714 | D8: 1054542.5 | E8: 4216357.1 | F8: 1.9644453e+11 | G8: 4.7199483e+10 | H8: 7.4499172e+11 | I8: 1.567436e+13 | J8: 1.7959055e+11 | K8: 8.5303716e+10 | L8: 2.8551193e+12 | M8: 1.9539365e+13 | N8: 2.0793766e+13 | O8: 0.64701593 | P8: 0.70855545 | Q8: 5129.1973 | R8: 1.252117
A9: =A8+1 -> 4 | B9: 11824150 | C9: 7317596.9 | D9: 1190277.6 | E9: 4333535 | F9: 1.857411e+11 | G9: 2.9840427e+10 | H9: 6.1262482e+11 | I9: 1.3710769e+13 | J9: 2.669452e+11 | K9: 1.2139076e+11 | L9: 2.9077421e+12 | M9: 1.7619472e+13 | N9: 1.8898784e+13 | O9: 0.63637686 | P9: 0.69644666 | Q9: 4661.7622 | R9: 1.0428604
A10: =A9+1 -> 5 | B10: 10747996 | C10: 9878268.6 | D10: 627462.58 | E10: 4063812.3 | F10: 2.2620551e+11 | G10: 3.9989974e+10 | H10: 6.6993497e+11 | I10: 1.2996553e+13 | J10: 1.9181173e+11 | K10: 1.025849e+11 | L10: 1.6265217e+12 | M10: 1.5587407e+13 | N10: 1.6717499e+13 | O10: 0.62017356 | P10: 0.68696752 | Q10: 4123.7048 | R10: 1.1115112
A11: =A10+1 -> 6 | B11: 12907256 | C11: 11095406 | D11: 851043.64 | E11: 7794969.3 | F11: 2.8579079e+11 | G11: 7.172305e+10 | H11: 6.9712865e+11 | I11: 1.6779538e+13 | J11: 7.2562416e+11 | K11: 1.1205279e+11 | L11: 2.2765743e+12 | M11: 2.0590918e+13 | N11: 2.1882311e+13 | O11: 0.60492864 | P11: 0.66096072 | Q11: 5397.7087 | R11: 1.2740267
A12: =A11+1 -> 7 | B12: 13295256 | C12: 20616062 | D12: 1265377.9 | E12: 4754640.6 | F12: 2.8106955e+11 | G12: 7.4886903e+10 | H12: 6.7650191e+11 | I12: 2.2496691e+13 | J12: 2.8425051e+11 | K12: 7.5418972e+10 | L12: 2.5088547e+12 | M12: 2.6041717e+13 | N12: 2.7551141e+13 | O12: 0.67867602 | P12: 0.75038101 | Q12: 6796.0386 | R12: 1.0711724
A13: =A12+1 -> 8 | B13: 7766040 | C13: 3759831.7 | D13: 1048886.9 | E13: 5774413.4 | F13: 2.2391531e+11 | G13: 4.5069496e+10 | H13: 5.2912975e+11 | I13: 7.7329362e+12 | J13: 3.3550427e+11 | K13: 8.5404481e+10 | L13: 2.1637958e+12 | M13: 1.0846771e+13 | N13: 1.1556377e+13 | O13: 0.52801931 | P13: 0.60001045 | Q13: 2850.611 | R13: 1.0492076
A14: =A13+1 -> 9 | B14: 11381257 | C14: 6399885.7 | D14: 1055425.9 | E14: 4281236.6 | F14: 2.5465364e+11 | G14: 4.9168745e+10 | H14: 5.7418892e+11 | I14: 1.1254871e+13 | J14: 2.6207696e+11 | K14: 7.3524809e+10 | L14: 2.3329048e+12 | M14: 1.4497567e+13 | N14: 1.5455282e+13 | O14: 0.61039055 | P14: 0.67619494 | Q14: 3812.3537 | R14: 1.0015053
A15: =A14+1 -> 10 | B15: 9470905.1 | C15: 6255986.6 | D15: 1599074.5 | E15: 7301098.9 | F15: 2.0889027e+11 | G15: 4.8358476e+10 | H15: 4.503743e+11 | I15: 1.0770212e+13 | J15: 5.836457e+11 | K15: 1.3664235e+11 | L15: 2.7452546e+12 | M15: 1.4686129e+13 | N15: 1.5624641e+13 | O15: 0.563839 | P15: 0.63615049 | Q15: 3854.1296 | R15: 0.89339219
A16: =A15+1 -> 11 | B16: 13892765 | C16: 7241459.7 | D16: 1235083.3 | E16: 4372639.3 | F16: 2.9394527e+11 | G16: 7.9880138e+10 | H16: 5.8400429e+11 | I16: 1.3400633e+13 | J16: 1.3050231e+11 | K16: 1.1068507e+11 | L16: 3.8236623e+12 | M16: 1.8049487e+13 | N16: 1.9190991e+13 | O16: 0.59536704 | P16: 0.67928339 | Q16: 4733.8408 | R16: 1.4919547
A17: =A16+1 -> 12 | B17: 8076797.9 | C17: 10982374 | D17: 719113.49 | E17: 2347167.1 | F17: 2.0018352e+11 | G17: 3.7654843e+10 | H17: 4.5998098e+11 | I17: 1.6851982e+13 | J17: 4.8278578e+10 | K17: 8.6545936e+10 | L17: 1.4578612e+12 | M17: 1.8904648e+13 | N17: 2.0040165e+13 | O17: 0.68380624 | P17: 0.74700343 | Q17: 4943.3067 | R17: 1.0693717
A18: =A17+1 -> 13 | B18: 10381616 | C18: 13295518 | D18: 1245905.6 | E18: 5302413 | F18: 2.4769289e+11 | G18: 4.6824446e+10 | H18: 6.9379967e+11 | I18: 2.0898793e+13 | J18: 3.9272154e+11 | K18: 9.6507412e+10 | L18: 2.7933905e+12 | M18: 2.4875212e+13 | N18: 2.6383973e+13 | O18: 0.67556663 | P18: 0.74106839 | Q18: 6508.1334 | R18: 1.0854725
... A5005: =A5004+1 -> 5000 | B5005: 11261204 | C5005: 4149684.7 | D5005: 870861.17 | E5005: 5621798.9 | F5005: 2.5820657e+11 | G5005: 5.3619857e+10 | H5005: 6.9536791e+11 | I5005: 7.518193e+12 | J5005: 2.6427871e+11 | K5005: 7.6815651e+10 | L5005: 1.5390776e+12 | M5005: 1.0093733e+13 | N5005: 1.0872616e+13 | O5005: 0.50509645 | P5005: 0.57315233 | Q5005: 2681.9477 | R5005: 0.95077812
